<mujoco model="panda_right">
  <compiler angle="radian" meshdir="assets" autolimits="true"/>

  <option integrator="implicitfast"/>

  <default>
    <default class="r_panda">
      <material specular="0.5" shininess="0.25"/>
      <joint armature="0.1" damping="1" axis="0 0 1" range="-2.8973 2.8973"/>
      <general dyntype="none" biastype="affine" ctrlrange="-2.8973 2.8973" forcerange="-87 87"/>
      <default class="r_finger">
        <joint axis="0 1 0" type="slide" range="0 0.04"/>
      </default>

      <default class="r_visual">
        <geom type="mesh" contype="0" conaffinity="0" group="2"/>
      </default>
      <default class="r_collision">
        <geom type="mesh" group="3"/>
        <default class="r_fingertip_pad_collision_1">
          <geom type="box" size="0.0085 0.004 0.0085" pos="0 0.0055 0.0445"/>
        </default>
        <default class="r_fingertip_pad_collision_2">
          <geom type="box" size="0.003 0.002 0.003" pos="0.0055 0.002 0.05"/>
        </default>
        <default class="r_fingertip_pad_collision_3">
          <geom type="box" size="0.003 0.002 0.003" pos="-0.0055 0.002 0.05"/>
        </default>
        <default class="r_fingertip_pad_collision_4">
          <geom type="box" size="0.003 0.002 0.0035" pos="0.0055 0.002 0.0395"/>
        </default>
        <default class="r_fingertip_pad_collision_5">
          <geom type="box" size="0.003 0.002 0.0035" pos="-0.0055 0.002 0.0395"/>
        </default>
      </default>
    </default>
  </default>

  <asset>
    <material class="r_panda" name="r_white" rgba="1 1 1 1"/>
    <material class="r_panda" name="r_off_white" rgba="0.901961 0.921569 0.929412 1"/>
    <material class="r_panda" name="r_black" rgba="0.25 0.25 0.25 1"/>
    <material class="r_panda" name="r_green" rgba="0 1 0 1"/>
    <material class="r_panda" name="r_light_blue" rgba="0.039216 0.541176 0.780392 1"/>

    <!-- Collision meshes -->
    <mesh name="r_link0_c" file="link0.stl"/>
    <mesh name="r_link1_c" file="link1.stl"/>
    <mesh name="r_link2_c" file="link2.stl"/>
    <mesh name="r_link3_c" file="link3.stl"/>
    <mesh name="r_link4_c" file="link4.stl"/>
    <mesh name="r_link5_c0" file="link5_collision_0.obj"/>
    <mesh name="r_link5_c1" file="link5_collision_1.obj"/>
    <mesh name="r_link5_c2" file="link5_collision_2.obj"/>
    <mesh name="r_link6_c" file="link6.stl"/>
    <mesh name="r_link7_c" file="link7.stl"/>
    <mesh name="r_hand_c" file="hand.stl"/>

    <!-- Visual meshes -->
    <mesh name="r_link0_0" file="link0_0.obj"/>
    <mesh name="r_link0_1" file="link0_1.obj"/>
    <mesh name="r_link0_2" file="link0_2.obj"/>
    <mesh name="r_link0_3" file="link0_3.obj"/>
    <mesh name="r_link0_4" file="link0_4.obj"/>
    <mesh name="r_link0_5" file="link0_5.obj"/>
    <mesh name="r_link0_7" file="link0_7.obj"/>
    <mesh name="r_link0_8" file="link0_8.obj"/>
    <mesh name="r_link0_9" file="link0_9.obj"/>
    <mesh name="r_link0_10" file="link0_10.obj"/>
    <mesh name="r_link0_11" file="link0_11.obj"/>

    <mesh name="r_link1" file="link1.obj"/>
    <mesh name="r_link2" file="link2.obj"/>

    <mesh name="r_link3_0" file="link3_0.obj"/>
    <mesh name="r_link3_1" file="link3_1.obj"/>
    <mesh name="r_link3_2" file="link3_2.obj"/>
    <mesh name="r_link3_3" file="link3_3.obj"/>

    <mesh name="r_link4_0" file="link4_0.obj"/>
    <mesh name="r_link4_1" file="link4_1.obj"/>
    <mesh name="r_link4_2" file="link4_2.obj"/>
    <mesh name="r_link4_3" file="link4_3.obj"/>

    <mesh name="r_link5_0" file="link5_0.obj"/>
    <mesh name="r_link5_1" file="link5_1.obj"/>
    <mesh name="r_link5_2" file="link5_2.obj"/>

    <mesh name="r_link6_0" file="link6_0.obj"/>
    <mesh name="r_link6_1" file="link6_1.obj"/>
    <mesh name="r_link6_2" file="link6_2.obj"/>
    <mesh name="r_link6_3" file="link6_3.obj"/>
    <mesh name="r_link6_4" file="link6_4.obj"/>
    <mesh name="r_link6_5" file="link6_5.obj"/>
    <mesh name="r_link6_6" file="link6_6.obj"/>
    <mesh name="r_link6_7" file="link6_7.obj"/>
    <mesh name="r_link6_8" file="link6_8.obj"/>
    <mesh name="r_link6_9" file="link6_9.obj"/>
    <mesh name="r_link6_10" file="link6_10.obj"/>
    <mesh name="r_link6_11" file="link6_11.obj"/>
    <mesh name="r_link6_12" file="link6_12.obj"/>
    <mesh name="r_link6_13" file="link6_13.obj"/>
    <mesh name="r_link6_14" file="link6_14.obj"/>
    <mesh name="r_link6_15" file="link6_15.obj"/>
    <mesh name="r_link6_16" file="link6_16.obj"/>

    <mesh name="r_link7_0" file="link7_0.obj"/>
    <mesh name="r_link7_1" file="link7_1.obj"/>
    <mesh name="r_link7_2" file="link7_2.obj"/>
    <mesh name="r_link7_3" file="link7_3.obj"/>
    <mesh name="r_link7_4" file="link7_4.obj"/>
    <mesh name="r_link7_5" file="link7_5.obj"/>
    <mesh name="r_link7_6" file="link7_6.obj"/>
    <mesh name="r_link7_7" file="link7_7.obj"/>

    <mesh name="r_hand_0" file="hand_0.obj"/>
    <mesh name="r_hand_1" file="hand_1.obj"/>
    <mesh name="r_hand_2" file="hand_2.obj"/>
    <mesh name="r_hand_3" file="hand_3.obj"/>
    <mesh name="r_hand_4" file="hand_4.obj"/>

    <mesh name="r_finger_0" file="finger_0.obj"/>
    <mesh name="r_finger_1" file="finger_1.obj"/>
  </asset>

  <worldbody>
    <light name="r_top" pos="0 0 2" mode="trackcom"/>
    <body name="r_link0" pos="0.45 0 0" quat="0.707 0 0 -0.707" childclass="r_panda">
      <inertial mass="0.629769" pos="-0.041018 -0.00014 0.049974"
        fullinertia="0.00315 0.00388 0.004285 8.2904e-7 0.00015 8.2299e-6"/>
      <geom mesh="link0_0" material="r_off_white" class="r_visual"/>
      <geom mesh="link0_1" material="r_black" class="r_visual"/>
      <geom mesh="link0_2" material="r_off_white" class="r_visual"/>
      <geom mesh="link0_3" material="r_black" class="r_visual"/>
      <geom mesh="link0_4" material="r_off_white" class="r_visual"/>
      <geom mesh="link0_5" material="r_black" class="r_visual"/>
      <geom mesh="link0_7" material="r_white" class="r_visual"/>
      <geom mesh="link0_8" material="r_white" class="r_visual"/>
      <geom mesh="link0_9" material="r_black" class="r_visual"/>
      <geom mesh="link0_10" material="r_off_white" class="r_visual"/>
      <geom mesh="link0_11" material="r_white" class="r_visual"/>
      <geom mesh="r_link0_c" class="r_collision"/>
      <body name="r_link1" pos="0 0 0.333">
        <inertial mass="4.970684" pos="0.003875 0.002081 -0.04762"
          fullinertia="0.70337 0.70661 0.0091170 -0.00013900 0.0067720 0.019169"/>
        <joint name="r_joint1"/>
        <geom material="r_white" mesh="link1" class="r_visual"/>
        <geom mesh="link1_c" class="r_collision"/>
        <body name="r_link2" quat="1 -1 0 0">
          <inertial mass="0.646926" pos="-0.003141 -0.02872 0.003495"
            fullinertia="0.0079620 2.8110e-2 2.5995e-2 -3.925e-3 1.0254e-2 7.04e-4"/>
          <joint name="r_joint2" range="-1.7628 1.7628"/>
          <geom material="r_white" mesh="link2" class="r_visual"/>
          <geom mesh="link2_c" class="r_collision"/>
          <body name="r_link3" pos="0 -0.316 0" quat="1 1 0 0">
            <joint name="r_joint3"/>
            <inertial mass="3.228604" pos="2.7518e-2 3.9252e-2 -6.6502e-2"
              fullinertia="3.7242e-2 3.6155e-2 1.083e-2 -4.761e-3 -1.1396e-2 -1.2805e-2"/>
            <geom mesh="link3_0" material="r_white" class="r_visual"/>
            <geom mesh="link3_1" material="r_white" class="r_visual"/>
            <geom mesh="link3_2" material="r_white" class="r_visual"/>
            <geom mesh="link3_3" material="r_black" class="r_visual"/>
            <geom mesh="link3_c" class="r_collision"/>
            <body name="r_link4" pos="0.0825 0 0" quat="1 1 0 0">
              <inertial mass="3.587895" pos="-5.317e-2 1.04419e-1 2.7454e-2"
                fullinertia="2.5853e-2 1.9552e-2 2.8323e-2 7.796e-3 -1.332e-3 8.641e-3"/>
              <joint name="r_joint4" range="-3.0718 -0.0698"/>
              <geom mesh="link4_0" material="r_white" class="r_visual"/>
              <geom mesh="link4_1" material="r_white" class="r_visual"/>
              <geom mesh="link4_2" material="r_black" class="r_visual"/>
              <geom mesh="link4_3" material="r_white" class="r_visual"/>
              <geom mesh="link4_c" class="r_collision"/>
              <body name="r_link5" pos="-0.0825 0.384 0" quat="1 -1 0 0">
                <inertial mass="1.225946" pos="-1.1953e-2 4.1065e-2 -3.8437e-2"
                  fullinertia="3.5549e-2 2.9474e-2 8.627e-3 -2.117e-3 -4.037e-3 2.29e-4"/>
                <joint name="r_joint5"/>
                <geom mesh="link5_0" material="r_black" class="r_visual"/>
                <geom mesh="link5_1" material="r_white" class="r_visual"/>
                <geom mesh="link5_2" material="r_white" class="r_visual"/>
                <geom mesh="link5_c0" class="r_collision"/>
                <geom mesh="link5_c1" class="r_collision"/>
                <geom mesh="link5_c2" class="r_collision"/>
                <body name="r_link6" quat="1 1 0 0">
                  <inertial mass="1.666555" pos="6.0149e-2 -1.4117e-2 -1.0517e-2"
                    fullinertia="1.964e-3 4.354e-3 5.433e-3 1.09e-4 -1.158e-3 3.41e-4"/>
                  <joint name="r_joint6" range="-0.0175 3.7525"/>
                  <geom mesh="link6_0" material="r_off_white" class="r_visual"/>
                  <geom mesh="link6_1" material="r_white" class="r_visual"/>
                  <geom mesh="link6_2" material="r_black" class="r_visual"/>
                  <geom mesh="link6_3" material="r_white" class="r_visual"/>
                  <geom mesh="link6_4" material="r_white" class="r_visual"/>
                  <geom mesh="link6_5" material="r_white" class="r_visual"/>
                  <geom mesh="link6_6" material="r_white" class="r_visual"/>
                  <geom mesh="link6_7" material="r_light_blue" class="r_visual"/>
                  <geom mesh="link6_8" material="r_light_blue" class="r_visual"/>
                  <geom mesh="link6_9" material="r_black" class="r_visual"/>
                  <geom mesh="link6_10" material="r_black" class="r_visual"/>
                  <geom mesh="link6_11" material="r_white" class="r_visual"/>
                  <geom mesh="link6_12" material="r_green" class="r_visual"/>
                  <geom mesh="link6_13" material="r_white" class="r_visual"/>
                  <geom mesh="link6_14" material="r_black" class="r_visual"/>
                  <geom mesh="link6_15" material="r_black" class="r_visual"/>
                  <geom mesh="link6_16" material="r_white" class="r_visual"/>
                  <geom mesh="link6_c" class="r_collision"/>
                  <body name="r_link7" pos="0.088 0 0" quat="1 1 0 0">
                    <inertial mass="7.35522e-01" pos="1.0517e-2 -4.252e-3 6.1597e-2"
                      fullinertia="1.2516e-2 1.0027e-2 4.815e-3 -4.28e-4 -1.196e-3 -7.41e-4"/>
                    <joint name="r_joint7"/>
                    <geom mesh="link7_0" material="r_white" class="r_visual"/>
                    <geom mesh="link7_1" material="r_black" class="r_visual"/>
                    <geom mesh="link7_2" material="r_black" class="r_visual"/>
                    <geom mesh="link7_3" material="r_black" class="r_visual"/>
                    <geom mesh="link7_4" material="r_black" class="r_visual"/>
                    <geom mesh="link7_5" material="r_black" class="r_visual"/>
                    <geom mesh="link7_6" material="r_black" class="r_visual"/>
                    <geom mesh="link7_7" material="r_white" class="r_visual"/>
                    <geom mesh="link7_c" class="r_collision"/>
                    <body name="r_hand" pos="0 0 0.107" quat="0.9238795 0 0 -0.3826834">
                      <inertial mass="0.73" pos="-0.01 0 0.03" diaginertia="0.001 0.0025 0.0017"/>
                      <geom mesh="r_hand_0" material="r_off_white" class="r_visual"/>
                      <geom mesh="r_hand_1" material="r_black" class="r_visual"/>
                      <geom mesh="r_hand_2" material="r_black" class="r_visual"/>
                      <geom mesh="r_hand_3" material="r_white" class="r_visual"/>
                      <geom mesh="r_hand_4" material="r_off_white" class="r_visual"/>
                      <geom mesh="r_hand_c" class="r_collision"/>
                      <body name="r_left_finger" pos="0 0 0.0584">
                        <inertial mass="0.015" pos="0 0 0" diaginertia="2.375e-6 2.375e-6 7.5e-7"/>
                        <joint name="r_finger_joint1" class="r_finger"/>
                        <geom mesh="r_finger_0" material="r_off_white" class="r_visual"/>
                        <geom mesh="r_finger_1" material="r_black" class="r_visual"/>
                        <geom mesh="r_finger_0" class="r_collision"/>
                        <geom class="r_fingertip_pad_collision_1"/>
                        <geom class="r_fingertip_pad_collision_2"/>
                        <geom class="r_fingertip_pad_collision_3"/>
                        <geom class="r_fingertip_pad_collision_4"/>
                        <geom class="r_fingertip_pad_collision_5"/>
                      </body>
                      <body name="r_right_finger" pos="0 0 0.0584" quat="0 0 0 1">
                        <inertial mass="0.015" pos="0 0 0" diaginertia="2.375e-6 2.375e-6 7.5e-7"/>
                        <joint name="r_finger_joint2" class="r_finger"/>
                        <geom mesh="r_finger_0" material="r_off_white" class="r_visual"/>
                        <geom mesh="r_finger_1" material="r_black" class="r_visual"/>
                        <geom mesh="r_finger_0" class="r_collision"/>
                        <geom class="r_fingertip_pad_collision_1"/>
                        <geom class="r_fingertip_pad_collision_2"/>
                        <geom class="r_fingertip_pad_collision_3"/>
                        <geom class="r_fingertip_pad_collision_4"/>
                        <geom class="r_fingertip_pad_collision_5"/>
                      </body>
                    </body>
                  </body>
                </body>
              </body>
            </body>
          </body>
        </body>
      </body>
    </body>
  </worldbody>

  <tendon>
    <fixed name="r_split">
      <joint joint="r_finger_joint1" coef="0.5"/>
      <joint joint="r_finger_joint2" coef="0.5"/>
    </fixed>
  </tendon>

  <equality>
    <joint joint1="r_finger_joint1" joint2="r_finger_joint2" solimp="0.95 0.99 0.001" solref="0.005 1"/>
  </equality>

  <actuator>
    <general class="r_panda" name="r_actuator1" joint="r_joint1" gainprm="4500" biasprm="0 -4500 -450"/>
    <general class="r_panda" name="r_actuator2" joint="r_joint2" gainprm="4500" biasprm="0 -4500 -450"
      ctrlrange="-1.7628 1.7628"/>
    <general class="r_panda" name="r_actuator3" joint="r_joint3" gainprm="3500" biasprm="0 -3500 -350"/>
    <general class="r_panda" name="r_actuator4" joint="r_joint4" gainprm="3500" biasprm="0 -3500 -350"
      ctrlrange="-3.0718 -0.0698"/>
    <general class="r_panda" name="r_actuator5" joint="r_joint5" gainprm="2000" biasprm="0 -2000 -200" forcerange="-12 12"/>
    <general class="r_panda" name="r_actuator6" joint="r_joint6" gainprm="2000" biasprm="0 -2000 -200" forcerange="-12 12"
      ctrlrange="-0.0175 3.7525"/>
    <general class="r_panda" name="r_actuator7" joint="r_joint7" gainprm="2000" biasprm="0 -2000 -200" forcerange="-12 12"/>
    <!-- Remap original ctrlrange (0, 0.04) to (0, 255): 0.04 * 100 / 255 = 0.01568627451 -->
    <general class="r_panda" name="r_actuator8" tendon="r_split" forcerange="-100 100" ctrlrange="0 255"
      gainprm="0.01568627451 0 0" biasprm="0 -100 -10"/>
  </actuator>

  <keyframe>
    <key name="r_home" qpos="0 0 0 -1.57079 0 1.57079 -0.7853 0.04 0.04" ctrl="0 0 0 -1.57079 0 1.57079 -0.7853 255"/>
  </keyframe>

  <contact>
    <exclude body1="r_link0" body2="r_link1"/>
  </contact>
</mujoco>
